<?xml version="1.0" ?>
<!-- =================================================================================== -->
<!-- |    This document was autogenerated by xacro from /home/gperry/github/inmoov_ros/inmoov_description/robots/inmoov.urdf.xacro | -->
<!-- |    EDITING THIS FILE BY HAND IS NOT RECOMMENDED                                 | -->
<!-- =================================================================================== -->
<robot name="inmoov">
  <!--xacro:property name="pi" value="3.1415926539"/-->
  <!-- meshlab steps taken from http://gazebosim.org/tutorials?tut=inertia -->
  <!-- assume material density is 1.0g per 1.0cm^2 -->
  <!-- ABS is 1.04g per 1.0cm^3 -->
  <!-- PLA is 1.25g per 1.0cm^3 -->
  <!-- based on https://github.com/ros-simulation/gazebo_ros_demos/blob/kinetic-devel/rrbot_description/urdf/rrbot.gazebo -->
  <!-- ros_control plugin -->
  <gazebo>
    <plugin filename="libgazebo_ros_control.so" name="gazebo_ros_control">
      <robotNamespace>/inmoov</robotNamespace>
      <robotSimType>gazebo_ros_control/DefaultRobotHWSim</robotSimType>
    </plugin>
  </gazebo>
  <!-- colors for torso links -->
  <gazebo reference="mid_stomach_link">
    <material>Gazebo/Grey</material>
  </gazebo>
  <gazebo reference="disk_link">
    <material>Gazebo/White</material>
  </gazebo>
  <gazebo reference="top_stomach_link">
    <material>Gazebo/Grey</material>
  </gazebo>
  <gazebo reference="torso_link">
    <material>Gazebo/Grey</material>
  </gazebo>
  <gazebo reference="kinect2_link">
    <material>Gazebo/DarkGrey</material>
  </gazebo>
  <gazebo reference="kinect2_ir_optical_frame_link">
    <material>Gazebo/DarkGrey</material>
  </gazebo>
  <gazebo reference="kinect2_rgb_optical_frame_link">
    <material>Gazebo/DarkGrey</material>
  </gazebo>
  <gazebo reference="chestplate_link">
    <material>Gazebo/White</material>
  </gazebo>
  <!-- colors for head links -->
  <gazebo reference="head_base_link">
    <material>Gazebo/Grey</material>
  </gazebo>
  <gazebo reference="head_link">
    <material>Gazebo/Grey</material>
  </gazebo>
  <gazebo reference="jaw_link">
    <material>Gazebo/White</material>
  </gazebo>
  <gazebo reference="skull_link">
    <material>Gazebo/White</material>
  </gazebo>
  <gazebo reference="left_ear_link">
    <material>Gazebo/Grey</material>
  </gazebo>
  <gazebo reference="right_ear_link">
    <material>Gazebo/Grey</material>
  </gazebo>
  <!-- colors for head links -->
  <gazebo reference="face_link">
    <material>Gazebo/White</material>
  </gazebo>
  <!-- colors for eye links -->
  <gazebo reference="l_eyesupport_link">
    <material>Gazebo/Grey</material>
  </gazebo>
  <gazebo reference="r_eyesupport_link">
    <material>Gazebo/Grey</material>
  </gazebo>
  <gazebo reference="l_camera_link">
    <material>Gazebo/DarkGrey</material>
  </gazebo>
  <gazebo reference="r_camera_link">
    <material>Gazebo/DarkGrey</material>
  </gazebo>
  <gazebo reference="l_eye_link">
    <material>Gazebo/White</material>
  </gazebo>
  <gazebo reference="r_eye_link">
    <material>Gazebo/White</material>
  </gazebo>
  <gazebo reference="l_iris_link">
    <material>Gazebo/SkyBlue</material>
  </gazebo>
  <gazebo reference="r_iris_link">
    <material>Gazebo/SkyBlue</material>
  </gazebo>
  <!-- colors for arm links -->
  <gazebo reference="l_shoulder_base_link">
    <material>Gazebo/Grey</material>
  </gazebo>
  <gazebo reference="r_shoulder_base_link">
    <material>Gazebo/Grey</material>
  </gazebo>
  <gazebo reference="l_shoulder_link">
    <material>Gazebo/Grey</material>
  </gazebo>
  <gazebo reference="r_shoulder_link">
    <material>Gazebo/Grey</material>
  </gazebo>
  <gazebo reference="l_bicep_link">
    <material>Gazebo/Grey</material>
  </gazebo>
  <gazebo reference="r_bicep_link">
    <material>Gazebo/Grey</material>
  </gazebo>
  <gazebo reference="l_bicepcover_link">
    <material>Gazebo/White</material>
  </gazebo>
  <gazebo reference="r_bicepcover_link">
    <material>Gazebo/White</material>
  </gazebo>
  <gazebo reference="l_forearm_link">
    <material>Gazebo/White</material>
  </gazebo>
  <gazebo reference="r_corearm_link">
    <material>Gazebo/White</material>
  </gazebo>
  <!-- colors for hand links -->
  <gazebo reference="l_hand_link">
    <material>Gazebo/Grey</material>
  </gazebo>
  <gazebo reference="r_hand_link">
    <material>Gazebo/Grey</material>
  </gazebo>
  <gazebo reference="l_thumb1_link">
    <material>Gazebo/Grey</material>
  </gazebo>
  <gazebo reference="r_thumb1_link">
    <material>Gazebo/Grey</material>
  </gazebo>
  <gazebo reference="l_thumb2_link">
    <material>Gazebo/Grey</material>
  </gazebo>
  <gazebo reference="r_thumb2_link">
    <material>Gazebo/Grey</material>
  </gazebo>
  <gazebo reference="l_thumb3_link">
    <material>Gazebo/Grey</material>
  </gazebo>
  <gazebo reference="r_thumb3_link">
    <material>Gazebo/Grey</material>
  </gazebo>
  <gazebo reference="l_index1_link">
    <material>Gazebo/Grey</material>
  </gazebo>
  <gazebo reference="r_index1_link">
    <material>Gazebo/Grey</material>
  </gazebo>
  <gazebo reference="l_index2_link">
    <material>Gazebo/Grey</material>
  </gazebo>
  <gazebo reference="r_index2_link">
    <material>Gazebo/Grey</material>
  </gazebo>
  <gazebo reference="l_index3_link">
    <material>Gazebo/Grey</material>
  </gazebo>
  <gazebo reference="r_index3_link">
    <material>Gazebo/Grey</material>
  </gazebo>
  <gazebo reference="l_middle1_link">
    <material>Gazebo/Grey</material>
  </gazebo>
  <gazebo reference="r_middle1_link">
    <material>Gazebo/Grey</material>
  </gazebo>
  <gazebo reference="l_middle2_link">
    <material>Gazebo/Grey</material>
  </gazebo>
  <gazebo reference="r_middle2_link">
    <material>Gazebo/Grey</material>
  </gazebo>
  <gazebo reference="l_middle3_link">
    <material>Gazebo/Grey</material>
  </gazebo>
  <gazebo reference="r_middle3_link">
    <material>Gazebo/Grey</material>
  </gazebo>
  <gazebo reference="l_ring1_link">
    <material>Gazebo/Grey</material>
  </gazebo>
  <gazebo reference="r_ring1_link">
    <material>Gazebo/Grey</material>
  </gazebo>
  <gazebo reference="l_ring2_link">
    <material>Gazebo/Grey</material>
  </gazebo>
  <gazebo reference="r_ring2_link">
    <material>Gazebo/Grey</material>
  </gazebo>
  <gazebo reference="l_ring3_link">
    <material>Gazebo/Grey</material>
  </gazebo>
  <gazebo reference="r_ring3_link">
    <material>Gazebo/Grey</material>
  </gazebo>
  <gazebo reference="l_ring4_link">
    <material>Gazebo/Grey</material>
  </gazebo>
  <gazebo reference="r_ring4_link">
    <material>Gazebo/Grey</material>
  </gazebo>
  <gazebo reference="l_pinky1_link">
    <material>Gazebo/Grey</material>
  </gazebo>
  <gazebo reference="r_pinky1_link">
    <material>Gazebo/Grey</material>
  </gazebo>
  <gazebo reference="l_pinky2_link">
    <material>Gazebo/Grey</material>
  </gazebo>
  <gazebo reference="r_pinky2_link">
    <material>Gazebo/Grey</material>
  </gazebo>
  <gazebo reference="l_pinky3_link">
    <material>Gazebo/Grey</material>
  </gazebo>
  <gazebo reference="r_pinky3_link">
    <material>Gazebo/Grey</material>
  </gazebo>
  <gazebo reference="l_pinky4_link">
    <material>Gazebo/Grey</material>
  </gazebo>
  <gazebo reference="r_pinky4_link">
    <material>Gazebo/Grey</material>
  </gazebo>
  <gazebo reference="l_handcover_link">
    <material>Gazebo/White</material>
  </gazebo>
  <gazebo reference="r_handcover_link">
    <material>Gazebo/White</material>
  </gazebo>
  <gazebo reference="l_cover_handring_link">
    <material>Gazebo/White</material>
  </gazebo>
  <gazebo reference="r_cover_handring_link">
    <material>Gazebo/White</material>
  </gazebo>
  <gazebo reference="l_cover_handpinky_link">
    <material>Gazebo/White</material>
  </gazebo>
  <gazebo reference="r_cover_handpinky_link">
    <material>Gazebo/White</material>
  </gazebo>
  <gazebo reference="l_cover_thumb_link">
    <material>Gazebo/White</material>
  </gazebo>
  <gazebo reference="r_cover_thumb_link">
    <material>Gazebo/White</material>
  </gazebo>
  <gazebo reference="l_cover_index_link">
    <material>Gazebo/White</material>
  </gazebo>
  <gazebo reference="r_cover_index_link">
    <material>Gazebo/White</material>
  </gazebo>
  <gazebo reference="l_cover_middle_link">
    <material>Gazebo/White</material>
  </gazebo>
  <gazebo reference="r_cover_middle_link">
    <material>Gazebo/White</material>
  </gazebo>
  <gazebo reference="l_cover_ring_link">
    <material>Gazebo/White</material>
  </gazebo>
  <gazebo reference="r_cover_ring_link">
    <material>Gazebo/White</material>
  </gazebo>
  <gazebo reference="l_cover_pinky_link">
    <material>Gazebo/White</material>
  </gazebo>
  <gazebo reference="r_cover_pinky_link">
    <material>Gazebo/White</material>
  </gazebo>
  <link name="world"/>
  <joint name="fixed" type="fixed">
    <parent link="world"/>
    <child link="base_link"/>
  </joint>
  <link name="base_link">
    <visual>
      <geometry>
        <cylinder length="0.11" radius="0.26"/>
      </geometry>
      <origin rpy="0 0 0" xyz="0 0 0.055"/>
      <material name="cbase">
        <color rgba="0.1 0.1 0.1 1"/>
      </material>
    </visual>
  </link>
  <joint name="base_to_pedestal_link" type="fixed">
    <parent link="base_link"/>
    <child link="pedestal_link"/>
    <origin rpy="0 0 0" xyz="0 0 0"/>
  </joint>
  <link name="pedestal_link">
    <visual>
      <geometry>
        <cylinder length="0.94" radius="0.0254"/>
      </geometry>
      <origin rpy="0 0 0" xyz="0 0 0.58"/>
      <material name="cbase">
        <color rgba="0.1 0.1 0.1 1"/>
      </material>
    </visual>
  </link>
  <link name="head_tilt_link">
    <visual>
      <geometry>
        <mesh filename="package://inmoov_meshes/meshes/virtual.stl" scale="0.001 0.001 0.001"/>
      </geometry>
      <origin rpy="0 0 3.1415" xyz="0 0 0"/>
      <material name="cframe">
        <color rgba="0.40 0.40 0.40 1"/>
      </material>
    </visual>
    <inertial>
      <mass value="0.001"/>
      <inertia ixx="1.66667e-10" ixy="0.0" ixz="0.0" iyy="1.66667e-10" iyz="0.0" izz="1.66667e-10"/>
    </inertial>
  </link>
  <joint name="pedestal_to_mid_stomach_joint" type="fixed">
    <parent link="pedestal_link"/>
    <child link="mid_stomach_link"/>
    <origin rpy="0 0 0" xyz="0 0 0"/>
  </joint>
  <link name="mid_stomach_link">
    <visual>
      <geometry>
        <mesh filename="package://inmoov_meshes/meshes/mid_stomach.stl" scale="0.001 0.001 0.001"/>
      </geometry>
      <origin rpy="0 0 0" xyz="0 0 1.152"/>
      <material name="cframe">
        <color rgba="0.40 0.40 0.40 1"/>
      </material>
    </visual>
    <inertial>
      <mass value="1710.217625"/>
      <inertia ixx="10.129861632" ixy="0.001797694125" ixz="0.205381024" iyy="4.40146688" iyz="-0.000721074" izz="10.623296512"/>
    </inertial>
  </link>
  <link name="disk_link">
    <visual>
      <geometry>
        <mesh filename="package://inmoov_meshes/meshes/disk.stl" scale="0.001 0.001 0.001"/>
      </geometry>
      <origin rpy="0 0 0" xyz="0 0 0"/>
      <material name="ccover">
        <color rgba="0.75 0.75 0.75 1.0"/>
      </material>
    </visual>
    <inertial>
      <mass value="178.96734375"/>
      <inertia ixx="0.518276192" ixy="-3.94440735e-07" ixz="0.012957092" iyy="0.264527408" iyz="1.5683143555000002e-05" izz="0.268095952"/>
    </inertial>
  </link>
  <link name="top_stomach_link">
    <visual>
      <geometry>
        <mesh filename="package://inmoov_meshes/meshes/top_stomach.stl" scale="0.001 0.001 0.001"/>
      </geometry>
      <origin rpy="0 0 0" xyz="0 0 0"/>
      <material name="cframe">
        <color rgba="0.40 0.40 0.40 1"/>
      </material>
    </visual>
    <inertial>
      <mass value="1144.88975"/>
      <inertia ixx="5.824147968" ixy="0.00452986" ixz="-0.222818176" iyy="4.174386432" iyz="0.00410783" izz="5.962789376"/>
    </inertial>
  </link>
  <link name="torso_link">
    <visual>
      <geometry>
        <mesh filename="package://inmoov_meshes/meshes/torso.stl" scale="0.001 0.001 0.001"/>
      </geometry>
      <origin rpy="0 0 0" xyz="0 0 0"/>
      <material name="cframe">
        <color rgba="0.40 0.40 0.40 1"/>
      </material>
    </visual>
    <inertial>
      <mass value="1923.29375"/>
      <inertia ixx="35.26709248" ixy="0.0069580865" ixz="0.730539008" iyy="25.724428288" iyz="-0.01522677" izz="13.365055488"/>
    </inertial>
  </link>
  <link name="kinect2_link">
    <visual>
      <geometry>
        <mesh filename="package://inmoov_meshes/meshes/kinectone.stl" scale="0.001 0.001 0.001"/>
      </geometry>
      <origin rpy="1.57 0 0" xyz="0 0 0"/>
      <material name="ckinect">
        <color rgba="0.1 0.1 0.1 1"/>
      </material>
    </visual>
    <inertial>
      <mass value="790.8319375"/>
      <inertia ixx="0.539265728" ixy="-0.008770675" ixz="-0.0023443175" iyy="3.865038592" iyz="0.025915652" izz="3.969101824"/>
    </inertial>
  </link>
  <link name="kinect2_ir_optical_frame">
    <visual>
      <geometry>
        <mesh filename="package://inmoov_meshes/meshes/kinectone.stl" scale="0.001 0.001 0.001"/>
      </geometry>
      <origin rpy="1.57 0 0" xyz="0 0 0"/>
      <material name="ckinect">
        <color rgba="0.1 0.1 0.1 1"/>
      </material>
    </visual>
    <inertial>
      <mass value="790.8319375"/>
      <inertia ixx="0.539265728" ixy="-0.008770675" ixz="-0.0023443175" iyy="3.865038592" iyz="0.025915652" izz="3.969101824"/>
    </inertial>
  </link>
  <link name="kinect2_rgb_optical_frame">
    <visual>
      <geometry>
        <mesh filename="package://inmoov_meshes/meshes/kinectone.stl" scale="0.001 0.001 0.001"/>
      </geometry>
      <origin rpy="1.57 0 0" xyz="0 0 0"/>
      <material name="ckinect">
        <color rgba="0.1 0.1 0.1 1"/>
      </material>
    </visual>
    <inertial>
      <mass value="790.8319375"/>
      <inertia ixx="0.539265728" ixy="-0.008770675" ixz="-0.0023443175" iyy="3.865038592" iyz="0.025915652" izz="3.969101824"/>
    </inertial>
  </link>
  <link name="chestplate_link">
    <visual>
      <geometry>
        <mesh filename="package://inmoov_meshes/meshes/chest.stl" scale="0.001 0.001 0.001"/>
      </geometry>
      <origin rpy="0 0 0" xyz="0 0 0"/>
      <material name="ccover">
        <color rgba="0.75 0.75 0.75 1.0"/>
      </material>
    </visual>
    <inertial>
      <mass value="755.6806875"/>
      <inertia ixx="7.996578816" ixy="-0.0004753828125" ixz="-0.051810308" iyy="3.795706624" iyz="0.011253427" izz="4.511691776"/>
    </inertial>
  </link>
  <joint name="waist_pan_joint" type="revolute">
    <axis xyz="0 0 1"/>
    <limit effort="1000.0" lower="-1.5707963267948966" upper="1.5707963267948966" velocity="0.0"/>
    <origin rpy="0 0 0" xyz="0 0 1.152"/>
    <parent link="mid_stomach_link"/>
    <child link="top_stomach_link"/>
  </joint>
  <joint name="disk_joint" type="fixed">
    <origin rpy="0 0 0" xyz="0.046 0 0.09"/>
    <parent link="top_stomach_link"/>
    <child link="disk_link"/>
  </joint>
  <joint name="waist_roll_joint" type="revolute">
    <axis xyz="1 0 0"/>
    <limit effort="1000.0" lower="0.2617993877991494" upper="-0.2617993877991494" velocity="0.0"/>
    <origin rpy="0 0 0" xyz="0 0 0.11"/>
    <parent link="top_stomach_link"/>
    <child link="torso_link"/>
  </joint>
  <joint name="chestplate_joint" type="fixed">
    <origin rpy="0 0 0" xyz="0.042 0 0.025"/>
    <parent link="torso_link"/>
    <child link="chestplate_link"/>
  </joint>
  <joint name="kinect2_joint" type="fixed">
    <origin rpy="-1.57 0 -1.57" xyz="0 0 0.066"/>
    <parent link="torso_link"/>
    <child link="kinect2_link"/>
  </joint>
  <joint name="kinect2_ir_optical_frame_joint" type="fixed">
    <origin rpy="-1.57 0 -1.57" xyz="0 0 0.066"/>
    <parent link="torso_link"/>
    <child link="kinect2_ir_optical_frame"/>
  </joint>
  <joint name="kinect2_rgb_optical_joint" type="fixed">
    <origin rpy="-1.57 0 -1.57" xyz="0 0 0.066"/>
    <parent link="torso_link"/>
    <child link="kinect2_rgb_optical_frame"/>
  </joint>
  <joint name="head_roll_joint" type="revolute">
    <axis xyz="1 0 0"/>
    <limit effort="1000.0" lower="-0.2617993877991494" upper="0.2617993877991494" velocity="0.0"/>
    <origin rpy="0 0 3.1415" xyz="-0.0315  -0.001 0.4551"/>
    <parent link="torso_link"/>
    <child link="head_tilt_link"/>
  </joint>
  <joint name="head_tilt_joint" type="revolute">
    <axis xyz="0 1 0"/>
    <limit effort="1000.0" lower="-0.3490658503988659" upper="0.3490658503988659" velocity="0.0"/>
    <origin rpy="0 0 3.1415" xyz="0 0 0"/>
    <parent link="head_tilt_link"/>
    <child link="head_base_link"/>
  </joint>
  <link name="head_base_link">
    <visual>
      <geometry>
        <mesh filename="package://inmoov_meshes/meshes/head_base.stl" scale="0.001 0.001 0.001"/>
      </geometry>
      <origin rpy="0 0 0" xyz="0 0 0"/>
      <material name="cframe">
        <color rgba="0.40 0.40 0.40 1"/>
      </material>
    </visual>
    <inertial>
      <mass value="43.50228125"/>
      <inertia ixx="0.025681996" ixy="1.829096875e-05" ixz="-0.00079066275" iyy="0.017327208" iyz="9.602263671999999e-06" izz="0.03535528"/>
    </inertial>
  </link>
  <link name="head_link">
    <visual>
      <geometry>
        <mesh filename="package://inmoov_meshes/meshes/head.stl" scale="0.001 0.001 0.001"/>
      </geometry>
      <origin rpy="0 0 0" xyz="0 0 0"/>
      <material name="cframe">
        <color rgba="0.40 0.40 0.40 1"/>
      </material>
    </visual>
    <inertial>
      <mass value="120.499460938"/>
      <inertia ixx="0.09250868" ixy="-0.000123085367188" ixz="-0.0078627105" iyy="0.150815008" iyz="0.0002850305625" izz="0.201933552"/>
    </inertial>
  </link>
  <link name="jaw_link">
    <visual>
      <geometry>
        <mesh filename="package://inmoov_meshes/meshes/jaw.stl" scale="0.001 0.001 0.001"/>
      </geometry>
      <origin rpy="0 0 0" xyz="0 0 0"/>
      <material name="ccover">
        <color rgba="0.75 0.75 0.75 1.0"/>
      </material>
    </visual>
    <inertial>
      <mass value="58.767261719000004"/>
      <inertia ixx="0.147272256" ixy="7.553278125e-05" ixz="0.055060208" iyy="0.134112088" iyz="-1.2159836913999999e-05" izz="0.156998304"/>
    </inertial>
  </link>
  <link name="skull_link">
    <visual>
      <geometry>
        <mesh filename="package://inmoov_meshes/meshes/skull.stl" scale="0.001 0.001 0.001"/>
      </geometry>
      <origin rpy="0 0 0" xyz="0 0 0"/>
      <material name="ccover">
        <color rgba="0.75 0.75 0.75 1.0"/>
      </material>
    </visual>
    <inertial>
      <mass value="422.3130625"/>
      <inertia ixx="1.82323712" ixy="0.006736614" ixz="0.115768256" iyy="2.48802176" iyz="-0.0004186136875" izz="2.440409856"/>
    </inertial>
  </link>
  <link name="left_ear_link">
    <visual>
      <geometry>
        <mesh filename="package://inmoov_meshes/meshes/earleftv1.stl" scale="0.001 0.001 0.001"/>
      </geometry>
      <origin rpy="0 0 0" xyz="0 0 0"/>
      <material name="cframe">
        <color rgba="0.40 0.40 0.40 1"/>
      </material>
    </visual>
    <inertial>
      <mass value="85.19796093800001"/>
      <inertia ixx="0.04423034" ixy="-0.001262894" ixz="0.005220882" iyy="0.08046712" iyz="-0.00048412846875" izz="0.04075106"/>
    </inertial>
  </link>
  <link name="right_ear_link">
    <visual>
      <geometry>
        <mesh filename="package://inmoov_meshes/meshes/earrightv1.stl" scale="0.001 0.001 0.001"/>
      </geometry>
      <origin rpy="0 0 0" xyz="0 0 0"/>
      <material name="cframe">
        <color rgba="0.40 0.40 0.40 1"/>
      </material>
    </visual>
    <inertial>
      <mass value="85.17540625"/>
      <inertia ixx="0.044218692" ixy="0.00126241425" ixz="0.0052192235" iyy="0.080448136" iyz="0.00048353196875" izz="0.040740816"/>
    </inertial>
  </link>
  <joint name="head_pan_joint" type="revolute">
    <axis xyz="0 0 1"/>
    <limit effort="1000.0" lower="-1.7453292519943295" upper="1.5707963267948966" velocity="0.0"/>
    <origin rpy="0 0 0" xyz="0 0 0.0245"/>
    <parent link="head_base_link"/>
    <child link="head_link"/>
  </joint>
  <joint name="jaw_joint" type="revolute">
    <axis xyz="0 1 0"/>
    <limit effort="1000.0" lower="0.0" upper="0.08726646259971647" velocity="0.0"/>
    <origin rpy="0 0.09 0" xyz="0.0375 0.0005 0.0437"/>
    <parent link="head_link"/>
    <child link="jaw_link"/>
  </joint>
  <joint name="skull_joint" type="fixed">
    <origin rpy="0 0 0" xyz="0.044 0 -0.0245"/>
    <parent link="head_link"/>
    <child link="skull_link"/>
  </joint>
  <joint name="left_ear_joint" type="fixed">
    <origin rpy="0 0 0" xyz="0.035 0.056 0.0437"/>
    <parent link="head_link"/>
    <child link="left_ear_link"/>
  </joint>
  <joint name="right_ear_joint" type="fixed">
    <origin rpy="0 0 0" xyz="0.035 -0.056 0.0437"/>
    <parent link="head_link"/>
    <child link="right_ear_link"/>
  </joint>
  <link name="face_link">
    <visual>
      <geometry>
        <mesh filename="package://inmoov_meshes/meshes/face.stl" scale="0.001 0.001 0.001"/>
      </geometry>
      <origin rpy="0 0 0" xyz="0 0 0"/>
      <material name="ccover">
        <color rgba="0.75 0.75 0.75 1.0"/>
      </material>
    </visual>
    <inertial>
      <mass value="46.55903125"/>
      <inertia ixx="0.060878272" ixy="6.9925132812e-05" ixz="0.00126951125" iyy="0.01978544" iyz="1.37124939e-06" izz="0.051128208"/>
    </inertial>
  </link>
  <joint name="eyes_tilt_joint" type="revolute">
    <axis xyz="0 1 0"/>
    <limit effort="1000.0" lower="0.2617993877991494" upper="-0.2617993877991494" velocity="0.0"/>
    <origin rpy="0 0 0" xyz="0 0 0"/>
    <parent link="face_link"/>
    <child link="eyesupport_link"/>
  </joint>
  <link name="eyesupport_link">
    <visual>
      <geometry>
        <mesh filename="package://inmoov_meshes/meshes/eyesupport.stl" scale="0.001 0.001 0.001"/>
      </geometry>
      <origin rpy="0 0 0" xyz="0 0 0"/>
      <material name="cframe">
        <color rgba="0.40 0.40 0.40 1"/>
      </material>
    </visual>
    <inertial>
      <mass value="27.550294922000003"/>
      <inertia ixx="0.02063259" ixy="0.0002853024375" ixz="-0.001400304" iyy="0.016763521" iyz="0.00183966425" izz="0.006981697"/>
    </inertial>
  </link>
  <link name="r_eyesupport_link">
    <visual>
      <geometry>
        <mesh filename="package://inmoov_meshes/meshes/r_eyesupport.stl" scale="0.001 0.001 0.001"/>
      </geometry>
      <origin rpy="0 0 0" xyz="0 0 0"/>
      <material name="cframe">
        <color rgba="0.40 0.40 0.40 1"/>
      </material>
    </visual>
    <inertial>
      <mass value="11.370105469"/>
      <inertia ixx="0.00243239225" ixy="6.9364135740000005e-06" ixz="-1.5166977539e-05" iyy="0.001752612875" iyz="0.0001608714375" izz="0.0008966528125"/>
    </inertial>
  </link>
  <link name="r_camera_link">
    <visual>
      <geometry>
        <mesh filename="package://inmoov_meshes/meshes/camera.stl" scale="0.001 0.001 0.001"/>
      </geometry>
      <origin rpy="0 0 0" xyz="0 0 0"/>
      <material name="ccamera">
        <color rgba="0.1 0.1 0.1 1"/>
      </material>
    </visual>
    <inertial>
      <mass value="2.4660676269999997"/>
      <inertia ixx="0.000240846265625" ixy="-6.775407099999999e-07" ixz="-4.6574912109999994e-06" iyy="7.5434351562e-05" iyz="-3.0454604490000003e-06" izz="0.000181402265625"/>
    </inertial>
  </link>
  <link name="r_eye_link">
    <visual>
      <geometry>
        <mesh filename="package://inmoov_meshes/meshes/eye.stl" scale="0.001 0.001 0.001"/>
      </geometry>
      <origin rpy="0 0 0" xyz="0 0 0"/>
      <material name="ceyeball">
        <color rgba="0.7 0.7 0.7 1"/>
      </material>
    </visual>
    <inertial>
      <mass value="4.659753906"/>
      <inertia ixx="0.0009137171875" ixy="2.418e-12" ixz="2.1174899999999998e-10" iyy="0.0004795756875" iyz="-3.262e-12" izz="0.0004755305"/>
    </inertial>
  </link>
  <link name="r_iris_link">
    <visual>
      <geometry>
        <mesh filename="package://inmoov_meshes/meshes/iris.stl" scale="0.001 0.001 0.001"/>
      </geometry>
      <origin rpy="0 0 0" xyz="0 0 0"/>
      <material name="ciris">
        <color rgba="0.25 0.41 0.88 1"/>
      </material>
    </visual>
    <inertial>
      <mass value="1.026836548"/>
      <inertia ixx="8.5819992188e-05" ixy="-1.07131e-10" ixz="-2.9419899999999997e-10" iyy="4.4821710937999995e-05" iyz="4.19771e-10" izz="4.4822714844e-05"/>
    </inertial>
  </link>
  <joint name="r_camera_joint" type="fixed">
    <origin rpy="0 0 0" xyz="-0.001 0 0"/>
    <parent link="r_eyesupport_link"/>
    <child link="r_camera_link"/>
  </joint>
  <joint name="r_eye_joint" type="fixed">
    <origin rpy="0 0 0" xyz="0.003 0 0"/>
    <parent link="r_eyesupport_link"/>
    <child link="r_eye_link"/>
  </joint>
  <joint name="r_iris_joint" type="fixed">
    <origin rpy="0 0 0" xyz="0.0061 0 0"/>
    <parent link="r_eyesupport_link"/>
    <child link="r_iris_link"/>
  </joint>
  <joint name="eyes_pan_joint" type="revolute">
    <axis xyz="0 0 1"/>
    <limit effort="1000.0" lower="-0.5235987755982988" upper="0.5235987755982988" velocity="0.0"/>
    <origin rpy="0 0 0" xyz="0 0.033 -0.0036"/>
    <parent link="eyesupport_link"/>
    <child link="r_eyesupport_link"/>
  </joint>
  <link name="l_eyesupport_link">
    <visual>
      <geometry>
        <mesh filename="package://inmoov_meshes/meshes/l_eyesupport.stl" scale="0.001 0.001 0.001"/>
      </geometry>
      <origin rpy="0 0 0" xyz="0 0 0"/>
      <material name="cframe">
        <color rgba="0.40 0.40 0.40 1"/>
      </material>
    </visual>
    <inertial>
      <mass value="11.370105469"/>
      <inertia ixx="0.00243239225" ixy="-6.936314941e-06" ixz="-1.5166963867e-05" iyy="0.00175261275" iyz="-0.0001608714375" izz="0.0008966526875"/>
    </inertial>
  </link>
  <link name="l_camera_link">
    <visual>
      <geometry>
        <mesh filename="package://inmoov_meshes/meshes/camera.stl" scale="0.001 0.001 0.001"/>
      </geometry>
      <origin rpy="0 0 0" xyz="0 0 0"/>
      <material name="ccamera">
        <color rgba="0.1 0.1 0.1 1"/>
      </material>
    </visual>
    <inertial>
      <mass value="2.4660676269999997"/>
      <inertia ixx="0.000240846265625" ixy="-6.775407099999999e-07" ixz="-4.6574912109999994e-06" iyy="7.5434351562e-05" iyz="-3.0454604490000003e-06" izz="0.000181402265625"/>
    </inertial>
  </link>
  <link name="l_eye_link">
    <visual>
      <geometry>
        <mesh filename="package://inmoov_meshes/meshes/eye.stl" scale="0.001 0.001 0.001"/>
      </geometry>
      <origin rpy="0 0 0" xyz="0 0 0"/>
      <material name="ceyeball">
        <color rgba="0.7 0.7 0.7 1"/>
      </material>
    </visual>
    <inertial>
      <mass value="4.659753906"/>
      <inertia ixx="0.0009137171875" ixy="2.418e-12" ixz="2.1174899999999998e-10" iyy="0.0004795756875" iyz="-3.262e-12" izz="0.0004755305"/>
    </inertial>
  </link>
  <link name="l_iris_link">
    <visual>
      <geometry>
        <mesh filename="package://inmoov_meshes/meshes/iris.stl" scale="0.001 0.001 0.001"/>
      </geometry>
      <origin rpy="0 0 0" xyz="0 0 0"/>
      <material name="ciris">
        <color rgba="0.25 0.41 0.88 1"/>
      </material>
    </visual>
    <inertial>
      <mass value="1.026836548"/>
      <inertia ixx="8.5819992188e-05" ixy="-1.07131e-10" ixz="-2.9419899999999997e-10" iyy="4.4821710937999995e-05" iyz="4.19771e-10" izz="4.4822714844e-05"/>
    </inertial>
  </link>
  <joint name="l_camera_joint" type="fixed">
    <origin rpy="0 0 0" xyz="-0.001 0 0"/>
    <parent link="l_eyesupport_link"/>
    <child link="l_camera_link"/>
  </joint>
  <joint name="l_eye_joint" type="fixed">
    <origin rpy="0 0 0" xyz="0.003 0 0"/>
    <parent link="l_eyesupport_link"/>
    <child link="l_eye_link"/>
  </joint>
  <joint name="l_iris_joint" type="fixed">
    <origin rpy="0 0 0" xyz="0.0061 0 0"/>
    <parent link="l_eyesupport_link"/>
    <child link="l_iris_link"/>
  </joint>
  <joint name="l_eye_pan_joint" type="revolute">
    <axis xyz="0 0 1"/>
    <limit effort="1000.0" lower="-0.5235987755982988" upper="0.5235987755982988" velocity="0.0"/>
    <mimic joint="eyes_pan_joint" multiplier="1" offset="0"/>
    <origin rpy="0 0 0" xyz="0 -0.033 -0.0036"/>
    <parent link="eyesupport_link"/>
    <child link="l_eyesupport_link"/>
  </joint>
  <joint name="face_joint" type="fixed">
    <origin rpy="0 0 0" xyz="0.0637 0 0.079"/>
    <parent link="skull_link"/>
    <child link="face_link"/>
  </joint>
  <link name="r_shoulder_base_link">
    <visual>
      <geometry>
        <mesh filename="package://inmoov_meshes/meshes/r_shoulder_base.stl" scale="0.001 0.001 0.001"/>
      </geometry>
      <origin rpy="0 0 0" xyz="0 0 0"/>
      <material name="cframe">
        <color rgba="0.40 0.40 0.40 1"/>
      </material>
    </visual>
    <inertial>
      <mass value="266.52696875"/>
      <inertia ixx="0.350410112" ixy="-0.0057351625" ixz="-0.011193818" iyy="0.3908856" iyz="0.045447476" izz="0.271458688"/>
    </inertial>
  </link>
  <link name="r_shoulder_link">
    <visual>
      <geometry>
        <mesh filename="package://inmoov_meshes/meshes/r_shoulder.stl" scale="0.001 0.001 0.001"/>
      </geometry>
      <origin rpy="0 0 0" xyz="0 0 0"/>
      <material name="cframe">
        <color rgba="0.40 0.40 0.40 1"/>
      </material>
    </visual>
    <inertial>
      <mass value="322.44334375"/>
      <inertia ixx="0.60134592" ixy="0.00343772975" ixz="-0.011761917" iyy="0.473865856" iyz="-0.114277" izz="0.500951584"/>
    </inertial>
  </link>
  <link name="r_bicep_link">
    <visual>
      <geometry>
        <mesh filename="package://inmoov_meshes/meshes/bicep.stl" scale="0.001 0.001 0.001"/>
      </geometry>
      <origin rpy="0 0 0" xyz="0 0 0"/>
      <material name="cframe">
        <color rgba="0.40 0.40 0.40 1"/>
      </material>
    </visual>
    <inertial>
      <mass value="281.91265625"/>
      <inertia ixx="1.283355392" ixy="-0.000200782203125" ixz="-0.224559104" iyy="1.399255168" iyz="0.0006545236875" izz="0.416621216"/>
    </inertial>
  </link>
  <link name="r_bicepcover_link">
    <visual>
      <geometry>
        <mesh filename="package://inmoov_meshes/meshes/bicepcover.stl" scale="0.001 0.001 0.001"/>
      </geometry>
      <origin rpy="0 0 0" xyz="0 0 0"/>
      <material name="ccover">
        <color rgba="0.75 0.75 0.75 1.0"/>
      </material>
    </visual>
    <inertial>
      <mass value="176.269609375"/>
      <inertia ixx="0.536349632" ixy="0.0009665334375" ixz="-0.069306768" iyy="0.625805568" iyz="0.0005666358125" izz="0.44191648"/>
    </inertial>
  </link>
  <link name="r_forearm_link">
    <visual>
      <geometry>
        <mesh filename="package://inmoov_meshes/meshes/r_forearm.stl" scale="0.001 0.001 0.001"/>
      </geometry>
      <origin rpy="0 0 0" xyz="0.001 0 0"/>
      <material name="ccover">
        <color rgba="0.75 0.75 0.75 1.0"/>
      </material>
    </visual>
    <inertial>
      <mass value="401.76659375"/>
      <inertia ixx="3.242307584" ixy="0.050011216" ixz="-0.14318512" iyy="3.24251008" iyz="0.086288976" izz="0.58458784"/>
    </inertial>
  </link>
  <joint name="r_shoulder_lift_joint" type="revolute">
    <axis xyz="0 1 0"/>
    <limit effort="1000.0" lower="0.7853981633974483" upper="-2.356194490192345" velocity="0.0"/>
    <origin rpy="0 0 0" xyz="0 -0.012 -0.04"/>
    <parent link="r_shoulder_base_link"/>
    <child link="r_shoulder_link"/>
  </joint>
  <joint name="r_upper_arm_roll_joint" type="revolute">
    <axis xyz="0 0 1"/>
    <limit effort="1000.0" lower="1.5707963267948966" upper="-1.5707963267948966" velocity="0.0"/>
    <origin rpy="0 0 0" xyz="0 -0.066 -0.060"/>
    <parent link="r_shoulder_link"/>
    <child link="r_bicep_link"/>
  </joint>
  <joint name="r_elbow_flex_joint" type="revolute">
    <axis xyz="0 1 0"/>
    <limit effort="1000.0" lower="-0.2617993877991494" upper="-1.3962634015954636" velocity="0.0"/>
    <origin rpy="0 0 0" xyz="-0.0278 0 -0.2235"/>
    <parent link="r_bicep_link"/>
    <child link="r_forearm_link"/>
  </joint>
  <joint name="r_bicepcover_joint" type="fixed">
    <origin rpy="0 0 0" xyz="0 0 0"/>
    <parent link="r_bicep_link"/>
    <child link="r_bicepcover_link"/>
  </joint>
  <joint name="r_shoulder_out_joint" type="revolute">
    <axis xyz="1 0 0"/>
    <limit effort="1000.0" lower="-0.08726646259971647" upper="-1.0471975511965976" velocity="0.0"/>
    <origin rpy="0 0 0" xyz="0 -0.143 0.298"/>
    <parent link="torso_link"/>
    <child link="r_shoulder_base_link"/>
  </joint>
  <link name="r_hand_link">
    <visual>
      <geometry>
        <mesh filename="package://inmoov_meshes/meshes/r_hand.stl" scale="0.001 0.001 0.001"/>
      </geometry>
      <origin rpy="0 0 0" xyz="0 0 0"/>
      <material name="cframe">
        <color rgba="0.40 0.40 0.40 1"/>
      </material>
    </visual>
    <inertial>
      <mass value="83.605"/>
      <inertia ixx="0.126485184" ixy="6.837660156e-06" ixz="-0.000139862265625" iyy="0.094925672" iyz="0.023795198" izz="0.037456164"/>
    </inertial>
  </link>
  <link name="r_thumb1_link">
    <visual>
      <geometry>
        <mesh filename="package://inmoov_meshes/meshes/r_thumb5_1.stl" scale="0.001 0.001 0.001"/>
      </geometry>
      <origin rpy="0 0 0" xyz="0 0 0"/>
      <material name="cframe">
        <color rgba="0.40 0.40 0.40 1"/>
      </material>
    </visual>
    <inertial>
      <mass value="10.044436523"/>
      <inertia ixx="0.001744373375" ixy="-4.0159230469000004e-05" ixz="4.101596875e-05" iyy="0.001225091875" iyz="0.00024317490625" izz="0.0011855675"/>
    </inertial>
  </link>
  <link name="r_thumb2_link">
    <visual>
      <geometry>
        <mesh filename="package://inmoov_meshes/meshes/thumb5_2.stl" scale="0.001 0.001 0.001"/>
      </geometry>
      <origin rpy="0 0 0" xyz="0 0 0"/>
      <material name="cframe">
        <color rgba="0.40 0.40 0.40 1"/>
      </material>
    </visual>
    <inertial>
      <mass value="7.511052246"/>
      <inertia ixx="0.0013042445" ixy="2.49766266e-07" ixz="4.2291962890000005e-06" iyy="0.001169623125" iyz="9.065935060000001e-07" izz="0.000555691125"/>
    </inertial>
  </link>
  <link name="r_thumb3_link">
    <visual>
      <geometry>
        <mesh filename="package://inmoov_meshes/meshes/thumb5_3.stl" scale="0.001 0.001 0.001"/>
      </geometry>
      <origin rpy="0 0 0" xyz="0 0 0"/>
      <material name="cframe">
        <color rgba="0.40 0.40 0.40 1"/>
      </material>
    </visual>
    <inertial>
      <mass value="5.812545409999999"/>
      <inertia ixx="0.0007149901875" ixy="-4.4194165e-07" ixz="-5.5290855469e-05" iyy="0.00073545675" iyz="4.97618683e-07" izz="0.00026050759375"/>
    </inertial>
  </link>
  <link name="r_index1_link">
    <visual>
      <geometry>
        <mesh filename="package://inmoov_meshes/meshes/index3_1.stl" scale="0.001 0.001 0.001"/>
      </geometry>
      <origin rpy="0 0 0" xyz="0 0 0"/>
      <material name="cframe">
        <color rgba="0.40 0.40 0.40 1"/>
      </material>
    </visual>
    <inertial>
      <mass value="4.8545507809999995"/>
      <inertia ixx="0.0007855188125" ixy="-1.13786087e-07" ixz="1.2465399413999999e-05" iyy="0.0007367950625" iyz="1.4965189210000001e-06" izz="0.000226730125"/>
    </inertial>
  </link>
  <link name="r_index2_link">
    <visual>
      <geometry>
        <mesh filename="package://inmoov_meshes/meshes/index3_2.stl" scale="0.001 0.001 0.001"/>
      </geometry>
      <origin rpy="0 0 0" xyz="0 0 0"/>
      <material name="cframe">
        <color rgba="0.40 0.40 0.40 1"/>
      </material>
    </visual>
    <inertial>
      <mass value="2.911548828"/>
      <inertia ixx="0.0002476975625" ixy="5.310544e-09" ixz="-1.3615135742e-05" iyy="0.0002445083125" iyz="7.016013789999999e-07" izz="9.105147656199999e-05"/>
    </inertial>
  </link>
  <link name="r_index3_link">
    <visual>
      <geometry>
        <mesh filename="package://inmoov_meshes/meshes/index3_3.stl" scale="0.001 0.001 0.001"/>
      </geometry>
      <origin rpy="0 0 0" xyz="0 0 0"/>
      <material name="cframe">
        <color rgba="0.40 0.40 0.40 1"/>
      </material>
    </visual>
    <inertial>
      <mass value="2.754759033"/>
      <inertia ixx="0.000240287703125" ixy="2.6071491000000003e-08" ixz="-1.3973435547e-05" iyy="0.000244506625" iyz="8.4088615e-08" izz="7.2536453125e-05"/>
    </inertial>
  </link>
  <link name="r_middle1_link">
    <visual>
      <geometry>
        <mesh filename="package://inmoov_meshes/meshes/middle3_1.stl" scale="0.001 0.001 0.001"/>
      </geometry>
      <origin rpy="0 0 0" xyz="0 0 0"/>
      <material name="cframe">
        <color rgba="0.40 0.40 0.40 1"/>
      </material>
    </visual>
    <inertial>
      <mass value="5.988140625"/>
      <inertia ixx="0.00111485875" ixy="-2.6224279e-08" ixz="1.7385302734000002e-05" iyy="0.00104555775" iyz="1.371758545e-06" izz="0.0003216090625"/>
    </inertial>
  </link>
  <link name="r_middle2_link">
    <visual>
      <geometry>
        <mesh filename="package://inmoov_meshes/meshes/middle3_2.stl" scale="0.001 0.001 0.001"/>
      </geometry>
      <origin rpy="0 0 0" xyz="0 0 0"/>
      <material name="cframe">
        <color rgba="0.40 0.40 0.40 1"/>
      </material>
    </visual>
    <inertial>
      <mass value="3.588543701"/>
      <inertia ixx="0.00035095146875" ixy="1.9666632e-08" ixz="-1.9434296875e-05" iyy="0.000346446375" iyz="1.214759033e-06" izz="0.000129022828125"/>
    </inertial>
  </link>
  <link name="r_middle3_link">
    <visual>
      <geometry>
        <mesh filename="package://inmoov_meshes/meshes/middle3_3.stl" scale="0.001 0.001 0.001"/>
      </geometry>
      <origin rpy="0 0 0" xyz="0 0 0"/>
      <material name="cframe">
        <color rgba="0.40 0.40 0.40 1"/>
      </material>
    </visual>
    <inertial>
      <mass value="3.395293457"/>
      <inertia ixx="0.00034045084375" ixy="3.217115e-08" ixz="-1.9707763672000002e-05" iyy="0.00034641909375" iyz="2.6280695e-08" izz="0.00010276375"/>
    </inertial>
  </link>
  <link name="r_ring1_link">
    <visual>
      <geometry>
        <mesh filename="package://inmoov_meshes/meshes/r_ring3_1.stl" scale="0.001 0.001 0.001"/>
      </geometry>
      <origin rpy="0 0 0" xyz="0 0 0"/>
      <material name="cframe">
        <color rgba="0.40 0.40 0.40 1"/>
      </material>
    </visual>
    <inertial>
      <mass value="10.81030957"/>
      <inertia ixx="0.0023923495" ixy="2.5959337891e-05" ixz="1.8166240234000002e-05" iyy="0.001249956375" iyz="-0.000426506625" izz="0.001810718375"/>
    </inertial>
  </link>
  <link name="r_ring2_link">
    <visual>
      <geometry>
        <mesh filename="package://inmoov_meshes/meshes/ring3_2.stl" scale="0.001 0.001 0.001"/>
      </geometry>
      <origin rpy="0 0 0" xyz="0 0 0"/>
      <material name="cframe">
        <color rgba="0.40 0.40 0.40 1"/>
      </material>
    </visual>
    <inertial>
      <mass value="4.222559082"/>
      <inertia ixx="0.0006227740625" ixy="5.753471e-09" ixz="1.0004874023000001e-05" iyy="0.0005840455625" iyz="7.29796631e-07" izz="0.000179666234375"/>
    </inertial>
  </link>
  <link name="r_ring3_link">
    <visual>
      <geometry>
        <mesh filename="package://inmoov_meshes/meshes/ring3_3.stl" scale="0.001 0.001 0.001"/>
      </geometry>
      <origin rpy="0 0 0" xyz="0 0 0"/>
      <material name="cframe">
        <color rgba="0.40 0.40 0.40 1"/>
      </material>
    </visual>
    <inertial>
      <mass value="2.530003662"/>
      <inertia ixx="0.000195998" ixy="1.0986977e-08" ixz="-1.0853751953000002e-05" iyy="0.00019348203125" iyz="6.78437927e-07" izz="7.205617968800001e-05"/>
    </inertial>
  </link>
  <link name="r_ring4_link">
    <visual>
      <geometry>
        <mesh filename="package://inmoov_meshes/meshes/ring3_4.stl" scale="0.001 0.001 0.001"/>
      </geometry>
      <origin rpy="0 0 0" xyz="0 0 0"/>
      <material name="cframe">
        <color rgba="0.40 0.40 0.40 1"/>
      </material>
    </visual>
    <inertial>
      <mass value="2.3937583009999996"/>
      <inertia ixx="0.000190133796875" ixy="1.7969458e-08" ixz="-1.1006313477e-05" iyy="0.0001934669375" iyz="1.4700538e-08" izz="5.7391125e-05"/>
    </inertial>
  </link>
  <link name="r_pinky1_link">
    <visual>
      <geometry>
        <mesh filename="package://inmoov_meshes/meshes/r_pinky3_1.stl" scale="0.001 0.001 0.001"/>
      </geometry>
      <origin rpy="0 0 0" xyz="0 0 0"/>
      <material name="cframe">
        <color rgba="0.40 0.40 0.40 1"/>
      </material>
    </visual>
    <inertial>
      <mass value="14.892949219"/>
      <inertia ixx="0.0043610115" ixy="3.6622980469000005e-05" ixz="2.9569984375e-05" iyy="0.00215359975" iyz="-0.001214404375" izz="0.003112752"/>
    </inertial>
  </link>
  <link name="r_pinky2_link">
    <visual>
      <geometry>
        <mesh filename="package://inmoov_meshes/meshes/pinky3_2.stl" scale="0.001 0.001 0.001"/>
      </geometry>
      <origin rpy="0 0 0" xyz="0 0 0"/>
      <material name="cframe">
        <color rgba="0.40 0.40 0.40 1"/>
      </material>
    </visual>
    <inertial>
      <mass value="3.0539240719999996"/>
      <inertia ixx="0.00036256315625" ixy="-3.0389627e-08" ixz="5.979022461e-06" iyy="0.00033987203125" iyz="6.579046630000001e-07" izz="0.00010569428125"/>
    </inertial>
  </link>
  <link name="r_pinky3_link">
    <visual>
      <geometry>
        <mesh filename="package://inmoov_meshes/meshes/pinky3_3.stl" scale="0.001 0.001 0.001"/>
      </geometry>
      <origin rpy="0 0 0" xyz="0 0 0"/>
      <material name="cframe">
        <color rgba="0.40 0.40 0.40 1"/>
      </material>
    </visual>
    <inertial>
      <mass value="1.8487075199999998"/>
      <inertia ixx="0.000116124148438" ixy="1.6077593e-08" ixz="-6.393164551e-06" iyy="0.00011466649218800001" iyz="3.9222839399999996e-07" izz="4.2715207030999996e-05"/>
    </inertial>
  </link>
  <link name="r_pinky4_link">
    <visual>
      <geometry>
        <mesh filename="package://inmoov_meshes/meshes/pinky3_4.stl" scale="0.001 0.001 0.001"/>
      </geometry>
      <origin rpy="0 0 0" xyz="0 0 0"/>
      <material name="cframe">
        <color rgba="0.40 0.40 0.40 1"/>
      </material>
    </visual>
    <inertial>
      <mass value="1.7482214360000001"/>
      <inertia ixx="0.000112612445312" ixy="1.0655196e-08" ixz="-6.518796875e-06" iyy="0.00011458659375" iyz="8.84516e-09" izz="3.3991617187999994e-05"/>
    </inertial>
  </link>
  <joint name="r_thumb1_joint" type="revolute">
    <axis xyz="0 0 1"/>
    <limit effort="1000.0" lower="-0.08726646259971647" upper="1.1344640137963142" velocity="0.0"/>
    <origin rpy="0.1 0 0" xyz="0 0.029 -0.0577"/>
    <mimic joint="r_thumb_joint" multiplier="0.75" offset="0"/>
    <parent link="r_hand_link"/>
    <child link="r_thumb1_link"/>
  </joint>
  <joint name="r_thumb_joint" type="revolute">
    <axis xyz="0 1 0"/>
    <limit effort="1000.0" lower="-0.08726646259971647" upper="1.1344640137963142" velocity="0.0"/>
    <origin rpy="0.825 -0.1 0.3" xyz="-0.00052 0.02725  -0.013"/>
    <parent link="r_thumb1_link"/>
    <child link="r_thumb2_link"/>
  </joint>
  <joint name="r_thumb3_joint" type="revolute">
    <axis xyz="0 1 0"/>
    <limit effort="1000.0" lower="-0.08726646259971647" upper="1.1344640137963142" velocity="0.0"/>
    <origin rpy="0 0 0" xyz="0 0 -0.035"/>
    <mimic joint="r_thumb_joint" multiplier="1" offset="0"/>
    <parent link="r_thumb2_link"/>
    <child link="r_thumb3_link"/>
  </joint>
  <joint name="r_index1_joint" type="revolute">
    <axis xyz="0 1 0"/>
    <limit effort="1000.0" lower="-0.08726646259971647" upper="1.4835298641951802" velocity="0.0"/>
    <origin rpy="0.1 0 0" xyz="-0.0015 0.0342  -0.119"/>
    <mimic joint="r_index_joint" multiplier="1" offset="0"/>
    <parent link="r_hand_link"/>
    <child link="r_index1_link"/>
  </joint>
  <joint name="r_index_joint" type="revolute">
    <axis xyz="0 1 0"/>
    <limit effort="1000.0" lower="-0.08726646259971647" upper="1.4835298641951802" velocity="0.0"/>
    <origin rpy="0 0 0" xyz="0 0.001 -0.03595"/>
    <parent link="r_index1_link"/>
    <child link="r_index2_link"/>
  </joint>
  <joint name="r_index3_joint" type="revolute">
    <axis xyz="0 1 0"/>
    <limit effort="1000.0" lower="-0.08726646259971647" upper="1.4835298641951802" velocity="0.0"/>
    <origin rpy="0 0 0" xyz="0 0 -0.024"/>
    <mimic joint="r_index_joint" multiplier="1" offset="0"/>
    <parent link="r_index2_link"/>
    <child link="r_index3_link"/>
  </joint>
  <joint name="r_middle1_joint" type="revolute">
    <axis xyz="0 1 0"/>
    <limit effort="1000.0" lower="-0.08726646259971647" upper="1.4835298641951802" velocity="0.0"/>
    <origin rpy="0 0 0" xyz="-0.00175 0.007  -0.12325"/>
    <mimic joint="r_middle_joint" multiplier="1" offset="0"/>
    <parent link="r_hand_link"/>
    <child link="r_middle1_link"/>
  </joint>
  <joint name="r_middle_joint" type="revolute">
    <axis xyz="0 1 0"/>
    <limit effort="1000.0" lower="-0.08726646259971647" upper="1.4835298641951802" velocity="0.0"/>
    <origin rpy="0 0 0" xyz="0 0.000 -0.0389"/>
    <parent link="r_middle1_link"/>
    <child link="r_middle2_link"/>
  </joint>
  <joint name="r_middle3_joint" type="revolute">
    <axis xyz="0 1 0"/>
    <limit effort="1000.0" lower="-0.08726646259971647" upper="1.4835298641951802" velocity="0.0"/>
    <origin rpy="0 0 0" xyz="0 0.0005 -0.0259"/>
    <mimic joint="r_middle_joint" multiplier="1" offset="0"/>
    <parent link="r_middle2_link"/>
    <child link="r_middle3_link"/>
  </joint>
  <joint name="r_ring1_joint" type="revolute">
    <axis xyz="0 0 1"/>
    <limit effort="1000.0" lower="-0.08726646259971647" upper="1.4835298641951802" velocity="0.0"/>
    <origin rpy="0.7 0 0" xyz="0 -0.00705 -0.0794"/>
    <mimic joint="r_ring_joint" multiplier="-0.1" offset="0"/>
    <parent link="r_hand_link"/>
    <child link="r_ring1_link"/>
  </joint>
  <joint name="r_ring_joint" type="revolute">
    <axis xyz="0 1 0"/>
    <limit effort="1000.0" lower="-0.08726646259971647" upper="1.4835298641951802" velocity="0.0"/>
    <origin rpy="-0.7775 0 0" xyz="0.00126 -0.0351 -0.0166"/>
    <parent link="r_ring1_link"/>
    <child link="r_ring2_link"/>
  </joint>
  <joint name="r_ring3_joint" type="revolute">
    <axis xyz="0 1 0"/>
    <limit effort="1000.0" lower="-0.08726646259971647" upper="1.4835298641951802" velocity="0.0"/>
    <origin rpy="0 0 0" xyz="0 0.0005 -0.0345"/>
    <mimic joint="r_ring_joint" multiplier="1" offset="0"/>
    <parent link="r_ring2_link"/>
    <child link="r_ring3_link"/>
  </joint>
  <joint name="r_ring4_joint" type="revolute">
    <axis xyz="0 1 0"/>
    <limit effort="1000.0" lower="-0.08726646259971647" upper="1.4835298641951802" velocity="0.0"/>
    <origin rpy="0 0 0" xyz="0 0.0004 -0.0229"/>
    <mimic joint="r_ring_joint" multiplier="1" offset="0"/>
    <parent link="r_ring3_link"/>
    <child link="r_ring4_link"/>
  </joint>
  <joint name="r_pinky1_joint" type="revolute">
    <axis xyz="0 0 1"/>
    <limit effort="1000.0" lower="-0.08726646259971647" upper="1.4835298641951802" velocity="0.0"/>
    <origin rpy="0.7 0 0" xyz="0 -0.027 -0.0555"/>
    <mimic joint="r_pinky_joint" multiplier="-0.1" offset="0"/>
    <parent link="r_hand_link"/>
    <child link="r_pinky1_link"/>
  </joint>
  <joint name="r_pinky_joint" type="revolute">
    <axis xyz="0 1 0"/>
    <limit effort="1000.0" lower="-0.08726646259971647" upper="1.4835298641951802" velocity="0.0"/>
    <origin rpy="-0.93 0 0" xyz="0 -0.046 -0.0228"/>
    <parent link="r_pinky1_link"/>
    <child link="r_pinky2_link"/>
  </joint>
  <joint name="r_pinky3_joint" type="revolute">
    <axis xyz="0 1 0"/>
    <limit effort="1000.0" lower="-0.08726646259971647" upper="1.4835298641951802" velocity="0.0"/>
    <origin rpy="0 0 0" xyz="0 0.0005 -0.031"/>
    <mimic joint="r_pinky_joint" multiplier="1" offset="0"/>
    <parent link="r_pinky2_link"/>
    <child link="r_pinky3_link"/>
  </joint>
  <joint name="r_pinky4_joint" type="revolute">
    <axis xyz="0 1 0"/>
    <limit effort="1000.0" lower="-0.08726646259971647" upper="1.4835298641951802" velocity="0.0"/>
    <origin rpy="0 0 0" xyz="0 0.0004 -0.0208"/>
    <mimic joint="r_pinky_joint" multiplier="1" offset="0"/>
    <parent link="r_pinky3_link"/>
    <child link="r_pinky4_link"/>
  </joint>
  <link name="r_handcover_link">
    <visual>
      <geometry>
        <mesh filename="package://inmoov_meshes/meshes/r_cover_hand.stl" scale="0.001 0.001 0.001"/>
      </geometry>
      <origin rpy="0 0 0" xyz="0 0 0"/>
      <material name="ccover">
        <color rgba="0.75 0.75 0.75 1.0"/>
      </material>
    </visual>
    <inertial>
      <mass value="39.850042969"/>
      <inertia ixx="0.043945364" ixy="0.00015029871875" ixz="-0.0006684343125" iyy="0.03162573" iyz="0.0078745195" izz="0.01280806"/>
    </inertial>
  </link>
  <link name="r_cover_handring_link">
    <visual>
      <geometry>
        <mesh filename="package://inmoov_meshes/meshes/r_cover_handring.stl" scale="0.001 0.001 0.001"/>
      </geometry>
      <origin rpy="0 0 0" xyz="0 0 0"/>
      <material name="ccover">
        <color rgba="0.75 0.75 0.75 1.0"/>
      </material>
    </visual>
    <inertial>
      <mass value="3.50753833"/>
      <inertia ixx="0.000430487" ixy="-5.051600585999999e-06" ixz="-2.255701172e-06" iyy="0.00028864628125" iyz="-5.947376100000001e-07" izz="0.00015917009375"/>
    </inertial>
  </link>
  <link name="r_cover_handpinky_link">
    <visual>
      <geometry>
        <mesh filename="package://inmoov_meshes/meshes/r_cover_handpinky.stl" scale="0.001 0.001 0.001"/>
      </geometry>
      <origin rpy="0 0 0" xyz="0 0 0"/>
      <material name="ccover">
        <color rgba="0.75 0.75 0.75 1.0"/>
      </material>
    </visual>
    <inertial>
      <mass value="3.887731445"/>
      <inertia ixx="0.0007326291875" ixy="-2.534063232e-06" ixz="2.594331299e-06" iyy="0.00057801175" iyz="-6.7645304688e-05" izz="0.0001684065625"/>
    </inertial>
  </link>
  <link name="r_cover_thumb_link">
    <visual>
      <geometry>
        <mesh filename="package://inmoov_meshes/meshes/r_cover_thumb.stl" scale="0.001 0.001 0.001"/>
      </geometry>
      <origin rpy="0 0 0" xyz="0 0 0"/>
      <material name="ccover">
        <color rgba="0.75 0.75 0.75 1.0"/>
      </material>
    </visual>
    <inertial>
      <mass value="3.250209961"/>
      <inertia ixx="0.0005435319375" ixy="-4.525456055e-06" ixz="8.495842773e-06" iyy="0.00044260215625" iyz="4.9077523437999994e-05" izz="0.000112376625"/>
    </inertial>
  </link>
  <link name="r_cover_index_link">
    <visual>
      <geometry>
        <mesh filename="package://inmoov_meshes/meshes/r_cover_index.stl" scale="0.001 0.001 0.001"/>
      </geometry>
      <origin rpy="0 0 0" xyz="0 0 0"/>
      <material name="ccover">
        <color rgba="0.75 0.75 0.75 1.0"/>
      </material>
    </visual>
    <inertial>
      <mass value="1.6353686520000001"/>
      <inertia ixx="0.000167985140625" ixy="-9.36647e-10" ixz="-1.5635599609e-05" iyy="0.0001404111875" iyz="-6.990110469999999e-07" izz="3.6513273438e-05"/>
    </inertial>
  </link>
  <link name="r_cover_middle_link">
    <visual>
      <geometry>
        <mesh filename="package://inmoov_meshes/meshes/r_cover_middle.stl" scale="0.001 0.001 0.001"/>
      </geometry>
      <origin rpy="0 0 0" xyz="0 0 0"/>
      <material name="ccover">
        <color rgba="0.75 0.75 0.75 1.0"/>
      </material>
    </visual>
    <inertial>
      <mass value="1.904471313"/>
      <inertia ixx="0.000234427671875" ixy="-1.1994104e-08" ixz="-2.2417498047e-05" iyy="0.000198775875" iyz="-9.45323303e-07" izz="4.7098675780999995e-05"/>
    </inertial>
  </link>
  <link name="r_cover_ring_link">
    <visual>
      <geometry>
        <mesh filename="package://inmoov_meshes/meshes/r_cover_ring.stl" scale="0.001 0.001 0.001"/>
      </geometry>
      <origin rpy="0 0 0" xyz="0 0 0"/>
      <material name="ccover">
        <color rgba="0.75 0.75 0.75 1.0"/>
      </material>
    </visual>
    <inertial>
      <mass value="1.4669017329999998"/>
      <inertia ixx="0.0001476946875" ixy="-1.216691284e-06" ixz="-1.2881797852e-05" iyy="0.000124547375" iyz="-4.381839844e-06" izz="3.0177607422e-05"/>
    </inertial>
  </link>
  <link name="r_cover_pinky_link">
    <visual>
      <geometry>
        <mesh filename="package://inmoov_meshes/meshes/r_cover_pinky.stl" scale="0.001 0.001 0.001"/>
      </geometry>
      <origin rpy="0 0 0" xyz="0 0 0"/>
      <material name="ccover">
        <color rgba="0.75 0.75 0.75 1.0"/>
      </material>
    </visual>
    <inertial>
      <mass value="1.2856073"/>
      <inertia ixx="0.000109421882812" ixy="-9.04252136e-07" ixz="-9.149e-06" iyy="9.051932031199999e-05" iyz="-2.714452637e-06" izz="2.4557162109e-05"/>
    </inertial>
  </link>
  <joint name="r_handcover_joint" type="fixed">
    <origin rpy="0 0 0" xyz="0.009 0.0192 -0.0977"/>
    <parent link="r_hand_link"/>
    <child link="r_handcover_link"/>
  </joint>
  <joint name="r_cover_handpinky_joint" type="fixed">
    <origin rpy="-0.7 0 0" xyz="0.01 -0.02025 -0.0071"/>
    <parent link="r_pinky1_link"/>
    <child link="r_cover_handpinky_link"/>
  </joint>
  <joint name="r_cover_handring_joint" type="fixed">
    <origin rpy="-0.7 0 0" xyz="0.009 -0.015 -0.0008"/>
    <parent link="r_ring1_link"/>
    <child link="r_cover_handring_link"/>
  </joint>
  <joint name="r_cover_middle_joint" type="fixed">
    <origin rpy="0 -0.05 0" xyz="0.0071 0 -0.012"/>
    <parent link="r_middle1_link"/>
    <child link="r_cover_middle_link"/>
  </joint>
  <joint name="r_cover_thumb_joint" type="fixed">
    <origin rpy="0.05 0 0" xyz="0.01 0.02125 0.0047"/>
    <parent link="r_thumb1_link"/>
    <child link="r_cover_thumb_link"/>
  </joint>
  <joint name="r_cover_index_joint" type="fixed">
    <origin rpy="0 0.05 0" xyz="0.0071 0 -0.012"/>
    <parent link="r_index1_link"/>
    <child link="r_cover_index_link"/>
  </joint>
  <joint name="r_cover_ring_joint" type="fixed">
    <origin rpy="0.1 -0.05 0" xyz="0.005 0 -0.011"/>
    <parent link="r_ring2_link"/>
    <child link="r_cover_ring_link"/>
  </joint>
  <joint name="r_cover_pinky_joint" type="fixed">
    <origin rpy="0.1 -0.05 0" xyz="0.005 0 -0.0105"/>
    <parent link="r_pinky2_link"/>
    <child link="r_cover_pinky_link"/>
  </joint>
  <joint name="r_wrist_roll_joint" type="revolute">
    <axis xyz="0 0 1"/>
    <limit effort="1000.0" lower="0.0" upper="-3.141592653589793" velocity="0.0"/>
    <origin rpy="0 0 0" xyz="-0.0144 0.01  -0.2885"/>
    <parent link="r_forearm_link"/>
    <child link="r_hand_link"/>
  </joint>
  <link name="l_shoulder_base_link">
    <visual>
      <geometry>
        <mesh filename="package://inmoov_meshes/meshes/l_shoulder_base.stl" scale="0.001 0.001 0.001"/>
      </geometry>
      <origin rpy="0 0 0" xyz="0 0 0"/>
      <material name="cframe">
        <color rgba="0.40 0.40 0.40 1"/>
      </material>
    </visual>
    <inertial>
      <mass value="266.52696875"/>
      <inertia ixx="0.35041024" ixy="0.0057351615" ixz="-0.011193821" iyy="0.390885728" iyz="-0.045447508" izz="0.27145872"/>
    </inertial>
  </link>
  <link name="l_shoulder_link">
    <visual>
      <geometry>
        <mesh filename="package://inmoov_meshes/meshes/l_shoulder.stl" scale="0.001 0.001 0.001"/>
      </geometry>
      <origin rpy="0 0 0" xyz="0 0 0"/>
      <material name="cframe">
        <color rgba="0.40 0.40 0.40 1"/>
      </material>
    </visual>
    <inertial>
      <mass value="322.44334375"/>
      <inertia ixx="0.601346048" ixy="-0.003437744" ixz="-0.011761914" iyy="0.473865952" iyz="0.11427704" izz="0.50095152"/>
    </inertial>
  </link>
  <link name="l_bicep_link">
    <visual>
      <geometry>
        <mesh filename="package://inmoov_meshes/meshes/bicep.stl" scale="0.001 0.001 0.001"/>
      </geometry>
      <origin rpy="0 0 0" xyz="0 0 0"/>
      <material name="cframe">
        <color rgba="0.40 0.40 0.40 1"/>
      </material>
    </visual>
    <inertial>
      <mass value="281.91265625"/>
      <inertia ixx="1.283355392" ixy="-0.000200782203125" ixz="-0.224559104" iyy="1.399255168" iyz="0.0006545236875" izz="0.416621216"/>
    </inertial>
  </link>
  <link name="l_bicepcover_link">
    <visual>
      <geometry>
        <mesh filename="package://inmoov_meshes/meshes/bicepcover.stl" scale="0.001 0.001 0.001"/>
      </geometry>
      <origin rpy="0 0 0" xyz="0 0 0"/>
      <material name="ccover">
        <color rgba="0.75 0.75 0.75 1.0"/>
      </material>
    </visual>
    <inertial>
      <mass value="176.269609375"/>
      <inertia ixx="0.536349632" ixy="0.0009665334375" ixz="-0.069306768" iyy="0.625805568" iyz="0.0005666358125" izz="0.44191648"/>
    </inertial>
  </link>
  <link name="l_forearm_link">
    <visual>
      <geometry>
        <mesh filename="package://inmoov_meshes/meshes/l_forearm.stl" scale="0.001 0.001 0.001"/>
      </geometry>
      <origin rpy="0 0 0" xyz="-0.001 0 0"/>
      <material name="ccover">
        <color rgba="0.75 0.75 0.75 1.0"/>
      </material>
    </visual>
    <inertial>
      <mass value="401.76659375"/>
      <inertia ixx="3.242308096" ixy="-0.050011216" ixz="-0.143185152" iyy="3.242510848" iyz="-0.086288992" izz="0.58458784"/>
    </inertial>
  </link>
  <joint name="l_shoulder_lift_joint" type="revolute">
    <axis xyz="0 1 0"/>
    <limit effort="1000.0" lower="0.7853981633974483" upper="-2.356194490192345" velocity="0.0"/>
    <origin rpy="0 0 0" xyz="0 0.012 -0.04"/>
    <parent link="l_shoulder_base_link"/>
    <child link="l_shoulder_link"/>
  </joint>
  <joint name="l_upper_arm_roll_joint" type="revolute">
    <axis xyz="0 0 1"/>
    <limit effort="1000.0" lower="-1.5707963267948966" upper="1.5707963267948966" velocity="0.0"/>
    <origin rpy="0 0 0" xyz="0 0.066 -0.060"/>
    <parent link="l_shoulder_link"/>
    <child link="l_bicep_link"/>
  </joint>
  <joint name="l_elbow_flex_joint" type="revolute">
    <axis xyz="0 1 0"/>
    <limit effort="1000.0" lower="-0.2617993877991494" upper="-1.4835298641951802" velocity="0.0"/>
    <origin rpy="0 0 0" xyz="-0.0278 0 -0.2235"/>
    <parent link="l_bicep_link"/>
    <child link="l_forearm_link"/>
  </joint>
  <joint name="l_bicepcover_joint" type="fixed">
    <origin rpy="0 0 0" xyz="0 0 0"/>
    <parent link="l_bicep_link"/>
    <child link="l_bicepcover_link"/>
  </joint>
  <joint name="l_shoulder_out_joint" type="revolute">
    <axis xyz="1 0 0"/>
    <limit effort="1000.0" lower="0.08726646259971647" upper="1.0471975511965976" velocity="0.0"/>
    <origin rpy="0 0 0" xyz="0 0.143 0.298"/>
    <parent link="torso_link"/>
    <child link="l_shoulder_base_link"/>
  </joint>
  <link name="l_hand_link">
    <visual>
      <geometry>
        <mesh filename="package://inmoov_meshes/meshes/l_hand.stl" scale="0.001 0.001 0.001"/>
      </geometry>
      <origin rpy="0 0 0" xyz="0 0 0"/>
      <material name="cframe">
        <color rgba="0.40 0.40 0.40 1"/>
      </material>
    </visual>
    <inertial>
      <mass value="83.605007812"/>
      <inertia ixx="0.126485224" ixy="-6.832961426e-06" ixz="-0.000139859234375" iyy="0.094925688" iyz="-0.023795198" izz="0.037456156"/>
    </inertial>
  </link>
  <link name="l_thumb1_link">
    <visual>
      <geometry>
        <mesh filename="package://inmoov_meshes/meshes/l_thumb5_1.stl" scale="0.001 0.001 0.001"/>
      </geometry>
      <origin rpy="0 0 0" xyz="0 0 0"/>
      <material name="cframe">
        <color rgba="0.40 0.40 0.40 1"/>
      </material>
    </visual>
    <inertial>
      <mass value="10.0444375"/>
      <inertia ixx="0.001744373625" ixy="4.0159183594e-05" ixz="4.1015949219000005e-05" iyy="0.001225092125" iyz="-0.000243175015625" izz="0.001185567625"/>
    </inertial>
  </link>
  <link name="l_thumb2_link">
    <visual>
      <geometry>
        <mesh filename="package://inmoov_meshes/meshes/thumb5_2.stl" scale="0.001 0.001 0.001"/>
      </geometry>
      <origin rpy="0 0 0" xyz="0 0 0"/>
      <material name="cframe">
        <color rgba="0.40 0.40 0.40 1"/>
      </material>
    </visual>
    <inertial>
      <mass value="7.511052246"/>
      <inertia ixx="0.0013042445" ixy="2.49766266e-07" ixz="4.2291962890000005e-06" iyy="0.001169623125" iyz="9.065935060000001e-07" izz="0.000555691125"/>
    </inertial>
  </link>
  <link name="l_thumb3_link">
    <visual>
      <geometry>
        <mesh filename="package://inmoov_meshes/meshes/thumb5_3.stl" scale="0.001 0.001 0.001"/>
      </geometry>
      <origin rpy="0 0 0" xyz="0 0 0"/>
      <material name="cframe">
        <color rgba="0.40 0.40 0.40 1"/>
      </material>
    </visual>
    <inertial>
      <mass value="5.812545409999999"/>
      <inertia ixx="0.0007149901875" ixy="-4.4194165e-07" ixz="-5.5290855469e-05" iyy="0.00073545675" iyz="4.97618683e-07" izz="0.00026050759375"/>
    </inertial>
  </link>
  <link name="l_index1_link">
    <visual>
      <geometry>
        <mesh filename="package://inmoov_meshes/meshes/index3_1.stl" scale="0.001 0.001 0.001"/>
      </geometry>
      <origin rpy="0 0 0" xyz="0 0 0"/>
      <material name="cframe">
        <color rgba="0.40 0.40 0.40 1"/>
      </material>
    </visual>
    <inertial>
      <mass value="4.8545507809999995"/>
      <inertia ixx="0.0007855188125" ixy="-1.13786087e-07" ixz="1.2465399413999999e-05" iyy="0.0007367950625" iyz="1.4965189210000001e-06" izz="0.000226730125"/>
    </inertial>
  </link>
  <link name="l_index2_link">
    <visual>
      <geometry>
        <mesh filename="package://inmoov_meshes/meshes/index3_2.stl" scale="0.001 0.001 0.001"/>
      </geometry>
      <origin rpy="0 0 0" xyz="0 0 0"/>
      <material name="cframe">
        <color rgba="0.40 0.40 0.40 1"/>
      </material>
    </visual>
    <inertial>
      <mass value="2.911548828"/>
      <inertia ixx="0.0002476975625" ixy="5.310544e-09" ixz="-1.3615135742e-05" iyy="0.0002445083125" iyz="7.016013789999999e-07" izz="9.105147656199999e-05"/>
    </inertial>
  </link>
  <link name="l_index3_link">
    <visual>
      <geometry>
        <mesh filename="package://inmoov_meshes/meshes/index3_3.stl" scale="0.001 0.001 0.001"/>
      </geometry>
      <origin rpy="0 0 0" xyz="0 0 0"/>
      <material name="cframe">
        <color rgba="0.40 0.40 0.40 1"/>
      </material>
    </visual>
    <inertial>
      <mass value="2.754759033"/>
      <inertia ixx="0.000240287703125" ixy="2.6071491000000003e-08" ixz="-1.3973435547e-05" iyy="0.000244506625" iyz="8.4088615e-08" izz="7.2536453125e-05"/>
    </inertial>
  </link>
  <link name="l_middle1_link">
    <visual>
      <geometry>
        <mesh filename="package://inmoov_meshes/meshes/middle3_1.stl" scale="0.001 0.001 0.001"/>
      </geometry>
      <origin rpy="0 0 0" xyz="0 0 0"/>
      <material name="cframe">
        <color rgba="0.40 0.40 0.40 1"/>
      </material>
    </visual>
    <inertial>
      <mass value="5.988140625"/>
      <inertia ixx="0.00111485875" ixy="-2.6224279e-08" ixz="1.7385302734000002e-05" iyy="0.00104555775" iyz="1.371758545e-06" izz="0.0003216090625"/>
    </inertial>
  </link>
  <link name="l_middle2_link">
    <visual>
      <geometry>
        <mesh filename="package://inmoov_meshes/meshes/middle3_2.stl" scale="0.001 0.001 0.001"/>
      </geometry>
      <origin rpy="0 0 0" xyz="0 0 0"/>
      <material name="cframe">
        <color rgba="0.40 0.40 0.40 1"/>
      </material>
    </visual>
    <inertial>
      <mass value="3.588543701"/>
      <inertia ixx="0.00035095146875" ixy="1.9666632e-08" ixz="-1.9434296875e-05" iyy="0.000346446375" iyz="1.214759033e-06" izz="0.000129022828125"/>
    </inertial>
  </link>
  <link name="l_middle3_link">
    <visual>
      <geometry>
        <mesh filename="package://inmoov_meshes/meshes/middle3_3.stl" scale="0.001 0.001 0.001"/>
      </geometry>
      <origin rpy="0 0 0" xyz="0 0 0"/>
      <material name="cframe">
        <color rgba="0.40 0.40 0.40 1"/>
      </material>
    </visual>
    <inertial>
      <mass value="3.395293457"/>
      <inertia ixx="0.00034045084375" ixy="3.217115e-08" ixz="-1.9707763672000002e-05" iyy="0.00034641909375" iyz="2.6280695e-08" izz="0.00010276375"/>
    </inertial>
  </link>
  <link name="l_ring1_link">
    <visual>
      <geometry>
        <mesh filename="package://inmoov_meshes/meshes/l_ring3_1.stl" scale="0.001 0.001 0.001"/>
      </geometry>
      <origin rpy="0 0 0" xyz="0 0 0"/>
      <material name="cframe">
        <color rgba="0.40 0.40 0.40 1"/>
      </material>
    </visual>
    <inertial>
      <mass value="10.81030957"/>
      <inertia ixx="0.002392349" ixy="-2.5959347656000003e-05" ixz="1.8166251953e-05" iyy="0.001249956375" iyz="0.00042650671875" izz="0.0018107185"/>
    </inertial>
  </link>
  <link name="l_ring2_link">
    <visual>
      <geometry>
        <mesh filename="package://inmoov_meshes/meshes/ring3_2.stl" scale="0.001 0.001 0.001"/>
      </geometry>
      <origin rpy="0 0 0" xyz="0 0 0"/>
      <material name="cframe">
        <color rgba="0.40 0.40 0.40 1"/>
      </material>
    </visual>
    <inertial>
      <mass value="4.222559082"/>
      <inertia ixx="0.0006227740625" ixy="5.753471e-09" ixz="1.0004874023000001e-05" iyy="0.0005840455625" iyz="7.29796631e-07" izz="0.000179666234375"/>
    </inertial>
  </link>
  <link name="l_ring3_link">
    <visual>
      <geometry>
        <mesh filename="package://inmoov_meshes/meshes/ring3_3.stl" scale="0.001 0.001 0.001"/>
      </geometry>
      <origin rpy="0 0 0" xyz="0 0 0"/>
      <material name="cframe">
        <color rgba="0.40 0.40 0.40 1"/>
      </material>
    </visual>
    <inertial>
      <mass value="2.530003662"/>
      <inertia ixx="0.000195998" ixy="1.0986977e-08" ixz="-1.0853751953000002e-05" iyy="0.00019348203125" iyz="6.78437927e-07" izz="7.205617968800001e-05"/>
    </inertial>
  </link>
  <link name="l_ring4_link">
    <visual>
      <geometry>
        <mesh filename="package://inmoov_meshes/meshes/ring3_4.stl" scale="0.001 0.001 0.001"/>
      </geometry>
      <origin rpy="0 0 0" xyz="0 0 0"/>
      <material name="cframe">
        <color rgba="0.40 0.40 0.40 1"/>
      </material>
    </visual>
    <inertial>
      <mass value="2.3937583009999996"/>
      <inertia ixx="0.000190133796875" ixy="1.7969458e-08" ixz="-1.1006313477e-05" iyy="0.0001934669375" iyz="1.4700538e-08" izz="5.7391125e-05"/>
    </inertial>
  </link>
  <link name="l_pinky1_link">
    <visual>
      <geometry>
        <mesh filename="package://inmoov_meshes/meshes/l_pinky3_1.stl" scale="0.001 0.001 0.001"/>
      </geometry>
      <origin rpy="0 0 0" xyz="0 0 0"/>
      <material name="cframe">
        <color rgba="0.40 0.40 0.40 1"/>
      </material>
    </visual>
    <inertial>
      <mass value="14.892949219"/>
      <inertia ixx="0.004361011" ixy="-3.6622921875e-05" ixz="2.9569964843999998e-05" iyy="0.00215359975" iyz="0.001214404125" izz="0.003112752"/>
    </inertial>
  </link>
  <link name="l_pinky2_link">
    <visual>
      <geometry>
        <mesh filename="package://inmoov_meshes/meshes/pinky3_2.stl" scale="0.001 0.001 0.001"/>
      </geometry>
      <origin rpy="0 0 0" xyz="0 0 0"/>
      <material name="cframe">
        <color rgba="0.40 0.40 0.40 1"/>
      </material>
    </visual>
    <inertial>
      <mass value="3.0539240719999996"/>
      <inertia ixx="0.00036256315625" ixy="-3.0389627e-08" ixz="5.979022461e-06" iyy="0.00033987203125" iyz="6.579046630000001e-07" izz="0.00010569428125"/>
    </inertial>
  </link>
  <link name="l_pinky3_link">
    <visual>
      <geometry>
        <mesh filename="package://inmoov_meshes/meshes/pinky3_3.stl" scale="0.001 0.001 0.001"/>
      </geometry>
      <origin rpy="0 0 0" xyz="0 0 0"/>
      <material name="cframe">
        <color rgba="0.40 0.40 0.40 1"/>
      </material>
    </visual>
    <inertial>
      <mass value="1.8487075199999998"/>
      <inertia ixx="0.000116124148438" ixy="1.6077593e-08" ixz="-6.393164551e-06" iyy="0.00011466649218800001" iyz="3.9222839399999996e-07" izz="4.2715207030999996e-05"/>
    </inertial>
  </link>
  <link name="l_pinky4_link">
    <visual>
      <geometry>
        <mesh filename="package://inmoov_meshes/meshes/pinky3_4.stl" scale="0.001 0.001 0.001"/>
      </geometry>
      <origin rpy="0 0 0" xyz="0 0 0"/>
      <material name="cframe">
        <color rgba="0.40 0.40 0.40 1"/>
      </material>
    </visual>
    <inertial>
      <mass value="1.7482214360000001"/>
      <inertia ixx="0.000112612445312" ixy="1.0655196e-08" ixz="-6.518796875e-06" iyy="0.00011458659375" iyz="8.84516e-09" izz="3.3991617187999994e-05"/>
    </inertial>
  </link>
  <joint name="l_thumb1_joint" type="revolute">
    <axis xyz="0 0 1"/>
    <limit effort="1000.0" lower="-0.08726646259971647" upper="1.1344640137963142" velocity="0.0"/>
    <origin rpy="-0.1 0 0" xyz="0 -0.029 -0.0577"/>
    <mimic joint="l_thumb_joint" multiplier="-0.75" offset="0"/>
    <parent link="l_hand_link"/>
    <child link="l_thumb1_link"/>
  </joint>
  <joint name="l_thumb_joint" type="revolute">
    <axis xyz="0 1 0"/>
    <limit effort="1000.0" lower="-0.08726646259971647" upper="1.1344640137963142" velocity="0.0"/>
    <origin rpy="-0.825 -0.1 -0.3" xyz="-0.00052 -0.02725  -0.013"/>
    <parent link="l_thumb1_link"/>
    <child link="l_thumb2_link"/>
  </joint>
  <joint name="l_thumb3_joint" type="revolute">
    <axis xyz="0 1 0"/>
    <limit effort="1000.0" lower="-0.08726646259971647" upper="1.1344640137963142" velocity="0.0"/>
    <origin rpy="0 0 0" xyz="0 0 -0.035"/>
    <mimic joint="l_thumb_joint" multiplier="1" offset="0"/>
    <parent link="l_thumb2_link"/>
    <child link="l_thumb3_link"/>
  </joint>
  <joint name="l_index1_joint" type="revolute">
    <axis xyz="0 1 0"/>
    <limit effort="1000.0" lower="-0.08726646259971647" upper="1.4835298641951802" velocity="0.0"/>
    <origin rpy="-0.1 0 0" xyz="-0.0015 -0.0342  -0.119"/>
    <mimic joint="l_index_joint" multiplier="1" offset="0"/>
    <parent link="l_hand_link"/>
    <child link="l_index1_link"/>
  </joint>
  <joint name="l_index_joint" type="revolute">
    <axis xyz="0 1 0"/>
    <limit effort="1000.0" lower="-0.08726646259971647" upper="1.4835298641951802" velocity="0.0"/>
    <origin rpy="0 0 0" xyz="0 0.001 -0.03595"/>
    <parent link="l_index1_link"/>
    <child link="l_index2_link"/>
  </joint>
  <joint name="l_index3_joint" type="revolute">
    <axis xyz="0 1 0"/>
    <limit effort="1000.0" lower="-0.08726646259971647" upper="1.4835298641951802" velocity="0.0"/>
    <origin rpy="0 0 0" xyz="0 0 -0.024"/>
    <mimic joint="l_index_joint" multiplier="1" offset="0"/>
    <parent link="l_index2_link"/>
    <child link="l_index3_link"/>
  </joint>
  <joint name="l_middle1_joint" type="revolute">
    <axis xyz="0 1 0"/>
    <limit effort="1000.0" lower="-0.08726646259971647" upper="1.4835298641951802" velocity="0.0"/>
    <origin rpy="0 0 0" xyz="-0.00175 -0.007  -0.12325"/>
    <mimic joint="l_middle_joint" multiplier="1" offset="0"/>
    <parent link="l_hand_link"/>
    <child link="l_middle1_link"/>
  </joint>
  <joint name="l_middle_joint" type="revolute">
    <axis xyz="0 1 0"/>
    <limit effort="1000.0" lower="-0.08726646259971647" upper="1.4835298641951802" velocity="0.0"/>
    <origin rpy="0 0 0" xyz="0 0.000 -0.0389"/>
    <parent link="l_middle1_link"/>
    <child link="l_middle2_link"/>
  </joint>
  <joint name="l_middle3_joint" type="revolute">
    <axis xyz="0 1 0"/>
    <limit effort="1000.0" lower="-0.08726646259971647" upper="1.4835298641951802" velocity="0.0"/>
    <origin rpy="0 0 0" xyz="0 0.0005 -0.0259"/>
    <mimic joint="l_middle_joint" multiplier="1" offset="0"/>
    <parent link="l_middle2_link"/>
    <child link="l_middle3_link"/>
  </joint>
  <joint name="l_ring1_joint" type="revolute">
    <axis xyz="0 0 1"/>
    <limit effort="1000.0" lower="-0.08726646259971647" upper="1.4835298641951802" velocity="0.0"/>
    <origin rpy="-0.7 0 0" xyz="0 0.00705 -0.0794"/>
    <mimic joint="l_ring_joint" multiplier="0.1" offset="0"/>
    <parent link="l_hand_link"/>
    <child link="l_ring1_link"/>
  </joint>
  <joint name="l_ring_joint" type="revolute">
    <axis xyz="0 1 0"/>
    <limit effort="1000.0" lower="-0.08726646259971647" upper="1.4835298641951802" velocity="0.0"/>
    <origin rpy="0.7775 0 0" xyz="0.00126 0.0351 -0.0166"/>
    <parent link="l_ring1_link"/>
    <child link="l_ring2_link"/>
  </joint>
  <joint name="l_ring3_joint" type="revolute">
    <axis xyz="0 1 0"/>
    <limit effort="1000.0" lower="-0.08726646259971647" upper="1.4835298641951802" velocity="0.0"/>
    <origin rpy="0 0 0" xyz="0 0.0005 -0.0345"/>
    <mimic joint="l_ring_joint" multiplier="1" offset="0"/>
    <parent link="l_ring2_link"/>
    <child link="l_ring3_link"/>
  </joint>
  <joint name="l_ring4_joint" type="revolute">
    <axis xyz="0 1 0"/>
    <limit effort="1000.0" lower="-0.08726646259971647" upper="1.4835298641951802" velocity="0.0"/>
    <origin rpy="0 0 0" xyz="0 0.0004 -0.0229"/>
    <mimic joint="l_ring_joint" multiplier="1" offset="0"/>
    <parent link="l_ring3_link"/>
    <child link="l_ring4_link"/>
  </joint>
  <joint name="l_pinky1_joint" type="revolute">
    <axis xyz="0 0 1"/>
    <limit effort="1000.0" lower="-0.08726646259971647" upper="1.4835298641951802" velocity="0.0"/>
    <origin rpy="-0.7 0 0" xyz="0 0.027 -0.0555"/>
    <mimic joint="l_pinky_joint" multiplier="0.1" offset="0"/>
    <parent link="l_hand_link"/>
    <child link="l_pinky1_link"/>
  </joint>
  <joint name="l_pinky_joint" type="revolute">
    <axis xyz="0 1 0"/>
    <limit effort="1000.0" lower="-0.08726646259971647" upper="1.4835298641951802" velocity="0.0"/>
    <origin rpy="0.93 0 0" xyz="0 0.046 -0.0228"/>
    <parent link="l_pinky1_link"/>
    <child link="l_pinky2_link"/>
  </joint>
  <joint name="l_pinky3_joint" type="revolute">
    <axis xyz="0 1 0"/>
    <limit effort="1000.0" lower="-0.08726646259971647" upper="1.4835298641951802" velocity="0.0"/>
    <origin rpy="0 0 0" xyz="0 0.0005 -0.031"/>
    <mimic joint="l_pinky_joint" multiplier="1" offset="0"/>
    <parent link="l_pinky2_link"/>
    <child link="l_pinky3_link"/>
  </joint>
  <joint name="l_pinky4_joint" type="revolute">
    <axis xyz="0 1 0"/>
    <limit effort="1000.0" lower="-0.08726646259971647" upper="1.4835298641951802" velocity="0.0"/>
    <origin rpy="0 0 0" xyz="0 0.0004 -0.0208"/>
    <mimic joint="l_pinky_joint" multiplier="1" offset="0"/>
    <parent link="l_pinky3_link"/>
    <child link="l_pinky4_link"/>
  </joint>
  <link name="l_handcover_link">
    <visual>
      <geometry>
        <mesh filename="package://inmoov_meshes/meshes/l_cover_hand.stl" scale="0.001 0.001 0.001"/>
      </geometry>
      <origin rpy="0 0 0" xyz="0 0 0"/>
      <material name="ccover">
        <color rgba="0.75 0.75 0.75 1.0"/>
      </material>
    </visual>
    <inertial>
      <mass value="39.850039062"/>
      <inertia ixx="0.043945356" ixy="-0.000150298984375" ixz="-0.0006684345625" iyy="0.031625718" iyz="-0.007874518" izz="0.012808058"/>
    </inertial>
  </link>
  <link name="l_cover_handring_link">
    <visual>
      <geometry>
        <mesh filename="package://inmoov_meshes/meshes/l_cover_handring.stl" scale="0.001 0.001 0.001"/>
      </geometry>
      <origin rpy="0 0 0" xyz="0 0 0"/>
      <material name="ccover">
        <color rgba="0.75 0.75 0.75 1.0"/>
      </material>
    </visual>
    <inertial>
      <mass value="3.507538086"/>
      <inertia ixx="0.00043048696875" ixy="5.0516035160000005e-06" ixz="-2.255701904e-06" iyy="0.00028864628125" iyz="5.94736511e-07" izz="0.00015917009375"/>
    </inertial>
  </link>
  <link name="l_cover_handpinky_link">
    <visual>
      <geometry>
        <mesh filename="package://inmoov_meshes/meshes/l_cover_handpinky.stl" scale="0.001 0.001 0.001"/>
      </geometry>
      <origin rpy="0 0 0" xyz="0 0 0"/>
      <material name="ccover">
        <color rgba="0.75 0.75 0.75 1.0"/>
      </material>
    </visual>
    <inertial>
      <mass value="3.887731445"/>
      <inertia ixx="0.0007326291875" ixy="2.534065674e-06" ixz="2.594330322e-06" iyy="0.00057801175" iyz="6.7645304688e-05" izz="0.0001684065625"/>
    </inertial>
  </link>
  <link name="l_cover_thumb_link">
    <visual>
      <geometry>
        <mesh filename="package://inmoov_meshes/meshes/l_cover_thumb.stl" scale="0.001 0.001 0.001"/>
      </geometry>
      <origin rpy="0 0 0" xyz="0 0 0"/>
      <material name="ccover">
        <color rgba="0.75 0.75 0.75 1.0"/>
      </material>
    </visual>
    <inertial>
      <mass value="3.250209717"/>
      <inertia ixx="0.0005435319375" ixy="4.52545459e-06" ixz="8.495841797e-06" iyy="0.00044260215625" iyz="-4.9077457031e-05" izz="0.000112376609375"/>
    </inertial>
  </link>
  <link name="l_cover_index_link">
    <visual>
      <geometry>
        <mesh filename="package://inmoov_meshes/meshes/l_cover_index.stl" scale="0.001 0.001 0.001"/>
      </geometry>
      <origin rpy="0 0 0" xyz="0 0 0"/>
      <material name="ccover">
        <color rgba="0.75 0.75 0.75 1.0"/>
      </material>
    </visual>
    <inertial>
      <mass value="1.6353686520000001"/>
      <inertia ixx="0.000167985140625" ixy="9.37079e-10" ixz="-1.5635599609e-05" iyy="0.0001404111875" iyz="6.99011658e-07" izz="3.6513273438e-05"/>
    </inertial>
  </link>
  <link name="l_cover_middle_link">
    <visual>
      <geometry>
        <mesh filename="package://inmoov_meshes/meshes/l_cover_middle.stl" scale="0.001 0.001 0.001"/>
      </geometry>
      <origin rpy="0 0 0" xyz="0 0 0"/>
      <material name="ccover">
        <color rgba="0.75 0.75 0.75 1.0"/>
      </material>
    </visual>
    <inertial>
      <mass value="1.904471313"/>
      <inertia ixx="0.000234427671875" ixy="1.1994666e-08" ixz="-2.2417498047e-05" iyy="0.000198775875" iyz="9.45323792e-07" izz="4.7098675780999995e-05"/>
    </inertial>
  </link>
  <link name="l_cover_ring_link">
    <visual>
      <geometry>
        <mesh filename="package://inmoov_meshes/meshes/l_cover_ring.stl" scale="0.001 0.001 0.001"/>
      </geometry>
      <origin rpy="0 0 0" xyz="0 0 0"/>
      <material name="ccover">
        <color rgba="0.75 0.75 0.75 1.0"/>
      </material>
    </visual>
    <inertial>
      <mass value="1.4669017329999998"/>
      <inertia ixx="0.0001476946875" ixy="1.2166915280000001e-06" ixz="-1.2881797852e-05" iyy="0.000124547375" iyz="4.381839844e-06" izz="3.0177607422e-05"/>
    </inertial>
  </link>
  <link name="l_cover_pinky_link">
    <visual>
      <geometry>
        <mesh filename="package://inmoov_meshes/meshes/l_cover_pinky.stl" scale="0.001 0.001 0.001"/>
      </geometry>
      <origin rpy="0 0 0" xyz="0 0 0"/>
      <material name="ccover">
        <color rgba="0.75 0.75 0.75 1.0"/>
      </material>
    </visual>
    <inertial>
      <mass value="1.2856073"/>
      <inertia ixx="0.000109421882812" ixy="9.04252441e-07" ixz="-9.149e-06" iyy="9.051932031199999e-05" iyz="2.714453125e-06" izz="2.4557162109e-05"/>
    </inertial>
  </link>
  <joint name="l_handcover_joint" type="fixed">
    <origin rpy="0 0 0" xyz="0.009 -0.0192 -0.0977"/>
    <parent link="l_hand_link"/>
    <child link="l_handcover_link"/>
  </joint>
  <joint name="l_cover_handpinky_joint" type="fixed">
    <origin rpy="0.7 0 0" xyz="0.01 0.02025 -0.0071"/>
    <parent link="l_pinky1_link"/>
    <child link="l_cover_handpinky_link"/>
  </joint>
  <joint name="l_cover_handring_joint" type="fixed">
    <origin rpy="0.7 0 0" xyz="0.009 0.015 -0.0008"/>
    <parent link="l_ring1_link"/>
    <child link="l_cover_handring_link"/>
  </joint>
  <joint name="l_cover_middle_joint" type="fixed">
    <origin rpy="0 0.05 0" xyz="0.0071 0 -0.012"/>
    <parent link="l_middle1_link"/>
    <child link="l_cover_middle_link"/>
  </joint>
  <joint name="l_cover_thumb_joint" type="fixed">
    <origin rpy="-0.05 0 0" xyz="0.01 -0.02125 0.0047"/>
    <parent link="l_thumb1_link"/>
    <child link="l_cover_thumb_link"/>
  </joint>
  <joint name="l_cover_index_joint" type="fixed">
    <origin rpy="0 -0.05 0" xyz="0.0071 0 -0.012"/>
    <parent link="l_index1_link"/>
    <child link="l_cover_index_link"/>
  </joint>
  <joint name="l_cover_ring_joint" type="fixed">
    <origin rpy="-0.1 0.05 0" xyz="0.005 0 -0.011"/>
    <parent link="l_ring2_link"/>
    <child link="l_cover_ring_link"/>
  </joint>
  <joint name="l_cover_pinky_joint" type="fixed">
    <origin rpy="-0.1 0.05 0" xyz="0.005 0 -0.0105"/>
    <parent link="l_pinky2_link"/>
    <child link="l_cover_pinky_link"/>
  </joint>
  <joint name="l_wrist_roll_joint" type="revolute">
    <axis xyz="0 0 1"/>
    <limit effort="1000.0" lower="3.141592653589793" upper="0.0" velocity="0.0"/>
    <origin rpy="0 0 0" xyz="-0.0144 -0.01  -0.2885"/>
    <parent link="l_forearm_link"/>
    <child link="l_hand_link"/>
  </joint>
</robot>
